Workbook

Sheet Packages Working
A1: S.NO. | B1: MODEL | C1: DESCRIPTION | D1: QTY. | E1: DISTRIBUTOR UNIT PRICE (POUND) | F1: DISTRIBUTOR AMOUNT (POUND) | G1: DISC. OFFERED | H1: NET BUYING (AFTER DISC.) | I1: HT COST (x147) | J1: CP (42%) | K1: Hi-Tech Margin | L1: LP (CP x 2) | M1: MRP (LP + 18%)
I2: 147 | J2: 1.42 | L2: 2
A3: 1 | B3: Quantum 112 surface Only | C3: X-Q112-WS | D3: 1 | E3: ='Q1'!F41 -> 9600 | F3: =D3*E3 -> 9600 | G3: 0.15 | H3: =F4-F4*G3 -> 8160 | I3: =H3*$I$2 -> 1199520 | J3: =ROUND(I3*$J$2,-2) -> 1703300 | K3: =(J3-I3)/J3 -> 0.29576704 | L3: =J3*$L$2 -> 3406600 | M3: =L3+L3*18% -> 4019788
F4: =SUM(F3) -> 9600
A6: 2 | B6: Quantum 112 Optic Kit | C6: MOD-Q1-OP-HMA | D6: 1 | E6: ='Q1'!F52 -> 4050 | F6: =D6*E6 -> 4050 | G6: 0.15 | H6: =F7-F7*G6 -> 3442.5 | I6: =H6*$I$2 -> 506047.5 | J6: =ROUND(I6*$J$2,-2) -> 718600 | K6: =(J6-I6)/J6 -> 0.29578695 | L6: =J6*$L$2 -> 1437200 | M6: =L6+L6*18% -> 1695896
F7: =SUM(F6) -> 4050
A9: 3 | B9: Quantum 112 System - MADI (with 1 # Nos of MQ Rack) | C9: X-Q112-WS | D9: 1 | E9: ='Q1'!F41 -> 9600 | F9: =D9*E9 -> 9600 | G9: 0.15 | H9: =F13-F13*G9 -> 13254.202 | I9: =H9*$I$2 -> 1948367.7 | J9: =ROUND(I9*$J$2,-2) -> 2766700 | K9: =(J9-I9)/J9 -> 0.29577921 | L9: =J9*$L$2 -> 5533400 | M9: =L9+L9*18% -> 6529412
C10: FC-Q112 | D10: 1 | E10: ='Q1'!F61 -> 875 | F10: =D10*E10 -> 875
C11: LEADS0049 - 100m BNC cable | D11: 2 | E11: =Racks!F211 -> 61.589257 | F11: =D11*E11 -> 123.17851
C12: X-MQ-RACK | D12: 1 | E12: =Racks!F124 -> 4995 | F12: =D12*E12 -> 4995
F13: =SUM(F9:F12) -> 15593.179
A15: 4 | B15: Quantum 112 System - Optics (with 1 # Nos of SD Rack) | C15: X-Q112-WS | D15: 1 | E15: ='Q1'!F41 -> 9600 | F15: =D15*E15 -> 9600 | G15: 0.15 | H15: =F22-F22*G15 -> 26924.281 | I15: =H15*$I$2 -> 3957869.3 | J15: =ROUND(I15*$J$2,-2) -> 5620200 | K15: =(J15-I15)/J15 -> 0.29577785 | L15: =J15*$L$2 -> 11240400 | M15: =L15*1.18 -> 13263672
C16: FC-Q112 | D16: 1 | E16: ='Q1'!F61 -> 875 | F16: =D16*E16 -> 875
C17: MOD-Q1-OP-HMA | D17: 1 | E17: ='Q1'!F52 -> 4050 | F17: =D17*E17 -> 4050
C18: X-SD-RACK-O | D18: 1 | E18: =Racks!F25 -> 5194.125 | F18: =D18*E18 -> 5194.125
C19: MOD-SDR-ADC32B | D19: 7 | E19: =Racks!F83 -> 895.5 | F19: =D19*E19 -> 6268.5
C20: MOD-SDR-DAC32B | D20: 7 | E20: =Racks!F89 -> 607.5 | F20: =D20*E20 -> 4252.5
C21: OPTIC-DRUM-150 | D21: 1 | E21: =Racks!F227 -> 1435.5 | F21: =D21*E21 -> 1435.5
F22: =SUM(F15:F21) -> 31675.625
A24: 5 | B24: Quantum 225 Single Screen System - MADI (with 1 # Nos of MQ Rack) | C24: X-Q225-WS | D24: 1 | E24: ='Q225'!F55 -> 14470 | F24: =D24*E24 -> 14470 | G24: 0.15 | H24: =F28-F28*G24 -> 18393.15 | I24: =H24*$I$2 -> 2703793.1 | J24: =ROUND(I24*$J$2,-2) -> 3839400 | K24: =(J24-I24)/J24 -> 0.29577719 | L24: =J24*$L$2 -> 7678800 | M24: =L24+L24*18% -> 9060984
C25: FC-Q225 | D25: 1 | E25: ='Q225'!F100 -> 1149 | F25: =D25*E25 -> 1149
C26: MOD-WAVES-Q2 | D26: 1 | E26: ='Q225'!F90 -> 1025 | F26: =D26*E26 -> 1025
C27: X-MQ-RACK | D27: 1 | E27: =Racks!F124 -> 4995 | F27: =D27*E27 -> 4995
F28: =SUM(F24:F27) -> 21639
A30: 6 | B30: Quantum 225 Single Screen System - MADI (with 2 # Nos of MQ Rack) | C30: X-Q225-WS | D30: 1 | E30: ='Q225'!F55 -> 14470 | F30: =D30*E30 -> 14470 | G30: 0.15 | H30: =F34-F34*G30 -> 22638.9 | I30: =H30*$I$2 -> 3327918.3 | J30: =ROUND(I30*$J$2,-2) -> 4725600 | K30: =(J30-I30)/J30 -> 0.29576809 | L30: =J30*$L$2 -> 9451200 | M30: =L30+L30*18% -> 11152416
C31: FC-Q225 | D31: 1 | E31: ='Q225'!F100 -> 1149 | F31: =D31*E31 -> 1149
C32: MOD-WAVES-Q2 | D32: 1 | E32: ='Q225'!F90 -> 1025 | F32: =D32*E32 -> 1025
C33: X-MQ-RACK | D33: 2 | E33: =Racks!F124 -> 4995 | F33: =D33*E33 -> 9990
F34: =SUM(F30:F33) -> 26634
A36: 7 | B36: Quantum 225 Single Screen System - Optics (with 1 # Nos of SD Rack) | C36: X-Q225-WS | D36: 1 | E36: ='Q225'!F55 -> 14470 | F36: =D36*E36 -> 14470 | G36: 0.15 | H36: =F44-F44*G36 -> 32167.931 | I36: =H36*$I$2 -> 4728685.9 | J36: =ROUND(I36*$J$2,-2) -> 6714700 | K36: =(J36-I36)/J36 -> 0.29577109 | L36: =J36*$L$2 -> 13429400 | M36: =L36*1.18 -> 15846692
C37: FC-Q225 | D37: 1 | E37: ='Q225'!F100 -> 1149 | F37: =D37*E37 -> 1149
C38: MOD-WAVES-Q2 | D38: 1 | E38: ='Q225'!F90 -> 1025 | F38: =D38*E38 -> 1025
C39: MOD-Q2-OP-HMA | D39: 1 | E39: ='Q225'!F66 -> 4050 | F39: =D39*E39 -> 4050
C40: X-SD-RACK-O | D40: 1 | E40: =Racks!F25 -> 5194.125 | F40: =D40*E40 -> 5194.125
C41: MOD-SDR-ADC32B | D41: 7 | E41: =Racks!F83 -> 895.5 | F41: =D41*E41 -> 6268.5
C42: MOD-SDR-DAC32B | D42: 7 | E42: =Racks!F89 -> 607.5 | F42: =D42*E42 -> 4252.5
C43: OPTIC-DRUM-150 | D43: 1 | E43: =Racks!F227 -> 1435.5 | F43: =D43*E43 -> 1435.5
F44: =SUM(F36:F43) -> 37844.625
A46: 8 | B46: Quantum 225 Dual Screen System - MADI (with 1 # Nos of MQ Rack) | C46: X-Q225-WS-DS | D46: 1 | E46: ='Q225'!G46 -> 14700 | F46: =D46*E46 -> 14700 | G46: Discount already applied 25% on Surface & 15% on rest | I46: =F50*$I$2 -> 3056666.6 | J46: =ROUND(I46*$J$2,-2) -> 4340500 | K46: =(J46-I46)/J46 -> 0.29578008 | L46: =J46*$L$2 -> 8681000 | M46: =L46+L46*18% -> 10243580
C47: FC-Q225 | D47: 1 | E47: ='Q225'!G100 -> 976.65 | F47: =D47*E47 -> 976.65
...

Sheet Q225
B2: DiGiCo Quantum 2 Distributor Price List
B4: Apr 2026
B6: Unit 10 Silverglade Business Park, Leatherhead Road
B7: Chessington, Surrey, KT9 2QL
B8: Tel; +44 1372 845600
B9: Fax; +44 1372 845656
B10: email; sales@digiconsoles.com
B11: web; www.digiconsoles.com
B13: FCA Glenrothes KY7 4NX. E&OE. Prices, Products and Specification are subject to change without notice.
B14: This price list supercedes all previous price lists.
A16: Product Code | B16: Description | E16: List (£) | F16: Distributor (£) | G16: Disc. (15%) | H16: HT Buy (INR) | I16: Customer Price | J16: Hi-Tech
G17: 0.15 | H17: 147 | I17: 1.42 | J17: Margin
A18: DiGiCo Quantum 225 Systems
B20: DiGiCo Quantum 225 system - MADI | E20: =ROUND(F20/0.55,0) -> 31935 | F20: 17564 | G20: =IF(F20-F20*$G$17=0,"",F20-F20*$G$17) -> 14929.4 | H20: =IFERROR(G20*$H$17,"") -> 2194621.8 | I20: =IFERROR(ROUND(H20*$I$17,0),"") -> 3116363 | J20: =IFERROR((I20-H20)/I20,"") -> 0.29577466
B21: 1 x Quantum 225 surface - 24+1 faders, 2 DMI slots, USB Audio I/O, 4 BNC MADI, 2 PSU, 2 GPIO | G21: =IF(F21-F21*$G$17=0,"",F21-F21*$G$17) | H21: =IFERROR(G21*$H$17,"") | I21: =IFERROR(ROUND(H21*$I$17,0),"") | J21: =IFERROR((I21-H21)/I21,"")
B22: 72 mono input channels, 36 mono output busses, | G22: =IF(F22-F22*$G$17=0,"",F22-F22*$G$17) | H22: =IFERROR(G22*$H$17,"") | I22: =IFERROR(ROUND(H22*$I$17,0),"") | J22: =IFERROR((I22-H22)/I22,"")
B23: 2 mono or stereo solo busses. LR or LCR master buss | G23: =IF(F23-F23*$G$17=0,"",F23-F23*$G$17) | H23: =IFERROR(G23*$H$17,"") | I23: =IFERROR(ROUND(H23*$I$17,0),"") | J23: =IFERROR((I23-H23)/I23,"")
B24: 12 x 12 matrix, 12 CG/VCA, 12 FX, 16 x 32 band graphic eq’s | G24: =IF(F24-F24*$G$17=0,"",F24-F24*$G$17) | H24: =IFERROR(G24*$H$17,"") | I24: =IFERROR(ROUND(H24*$I$17,0),"") | J24: =IFERROR((I24-H24)/I24,"")
B25: 32 Nodal Processors, 24 Mustard Processors, 6 Spice FX | G25: =IF(F25-F25*$G$17=0,"",F25-F25*$G$17) | H25: =IFERROR(G25*$H$17,"") | I25: =IFERROR(ROUND(H25*$I$17,0),"") | J25: =IFERROR((I25-H25)/I25,"")
B26: Local I/O 8 x Mic/Line inputs, 8 x Line outputs, 8 x AES I/O mono stream, mounting bracket, dust cover, carton | G26: =IF(F26-F26*$G$17=0,"",F26-F26*$G$17) | H26: =IFERROR(G26*$H$17,"") | I26: =IFERROR(ROUND(H26*$I$17,0),"") | J26: =IFERROR((I26-H26)/I26,"")
B27: 1 x Quantum MADI Rack, 2 BNC MADI, dual PSU - 48 mic/line in / up to 24 line out / up to 8 AES output (mono), carton | G27: =IF(F27-F27*$G$17=0,"",F27-F27*$G$17) | H27: =IFERROR(G27*$H$17,"") | I27: =IFERROR(ROUND(H27*$I$17,0),"") | J27: =IFERROR((I27-H27)/I27,"")
B28: 2 x 100m BNC Cables | G28: =IF(F28-F28*$G$17=0,"",F28-F28*$G$17) | H28: =IFERROR(G28*$H$17,"") | I28: =IFERROR(ROUND(H28*$I$17,0),"") | J28: =IFERROR((I28-H28)/I28,"")
G29: =IF(F29-F29*$G$17=0,"",F29-F29*$G$17) | H29: =IFERROR(G29*$H$17,"") | I29: =IFERROR(ROUND(H29*$I$17,0),"") | J29: =IFERROR((I29-H29)/I29,"")
B30: DiGiCo Quantum 225 system - DANTE | E30: =ROUND(F30/0.55,0) -> 33751 | F30: 18563 | G30: =IF(F30-F30*$G$17=0,"",F30-F30*$G$17) -> 15778.55 | H30: =IFERROR(G30*$H$17,"") -> 2319446.9 | I30: =IFERROR(ROUND(H30*$I$17,0),"") -> 3293615 | J30: =IFERROR((I30-H30)/I30,"") -> 0.29577475
B31: 1 x Quantum 225 surface - 24+1 faders, 2 DMI slots, USB Audio I/O, 4 BNC MADI, 2 PSU, 2 GPIO | G31: =IF(F31-F31*$G$17=0,"",F31-F31*$G$17) | H31: =IFERROR(G31*$H$17,"") | I31: =IFERROR(ROUND(H31*$I$17,0),"") | J31: =IFERROR((I31-H31)/I31,"")
B32: 72 mono input channels, 36 mono output busses, | G32: =IF(F32-F32*$G$17=0,"",F32-F32*$G$17) | H32: =IFERROR(G32*$H$17,"") | I32: =IFERROR(ROUND(H32*$I$17,0),"") | J32: =IFERROR((I32-H32)/I32,"")
B33: 2 mono or stereo solo busses. LR or LCR master buss | G33: =IF(F33-F33*$G$17=0,"",F33-F33*$G$17) | H33: =IFERROR(G33*$H$17,"") | I33: =IFERROR(ROUND(H33*$I$17,0),"") | J33: =IFERROR((I33-H33)/I33,"")
B34: 12 x 12 matrix, 12 CG/VCA, 12 FX, 16 x 32 band graphic eq’s | G34: =IF(F34-F34*$G$17=0,"",F34-F34*$G$17) | H34: =IFERROR(G34*$H$17,"") | I34: =IFERROR(ROUND(H34*$I$17,0),"") | J34: =IFERROR((I34-H34)/I34,"")
B35: 32 Nodal Processors, 24 Mustard Processors, 6 Spice FX | G35: =IF(F35-F35*$G$17=0,"",F35-F35*$G$17) | H35: =IFERROR(G35*$H$17,"") | I35: =IFERROR(ROUND(H35*$I$17,0),"") | J35: =IFERROR((I35-H35)/I35,"")
B36: Local I/O 8 x Mic/Line inputs, 8 x Line outputs, 8 x AES I/O mono stream, mounting bracket, dust cover, carton | G36: =IF(F36-F36*$G$17=0,"",F36-F36*$G$17) | H36: =IFERROR(G36*$H$17,"") | I36: =IFERROR(ROUND(H36*$I$17,0),"") | J36: =IFERROR((I36-H36)/I36,"")
B37: 1 x DMI Dante 64@96 SRC I/O card, 2 etherCON, 1 RJ45 | G37: =IF(F37-F37*$G$17=0,"",F37-F37*$G$17) | H37: =IFERROR(G37*$H$17,"") | I37: =IFERROR(ROUND(H37*$I$17,0),"") | J37: =IFERROR((I37-H37)/I37,"") | M37: 3
B38: 1 x Quantum Dante Rack, 2 etherCON, dual PSU - 48 mic/line in / up to 24 line out / up to 8 AES output (mono), carton | G38: =IF(F38-F38*$G$17=0,"",F38-F38*$G$17) | H38: =IFERROR(G38*$H$17,"") | I38: =IFERROR(ROUND(H38*$I$17,0),"") | J38: =IFERROR((I38-H38)/I38,"") | M38: 8.25
B39: 1 x 75m CAT6 Cable | G39: =IF(F39-F39*$G$17=0,"",F39-F39*$G$17) | H39: =IFERROR(G39*$H$17,"") | I39: =IFERROR(ROUND(H39*$I$17,0),"") | J39: =IFERROR((I39-H39)/I39,"") | M39: 1
G40: =IF(F40-F40*$G$17=0,"",F40-F40*$G$17) | H40: =IFERROR(G40*$H$17,"") | I40: =IFERROR(ROUND(H40*$I$17,0),"") | J40: =IFERROR((I40-H40)/I40,"")
B41: The product codes for Q225 systems no longer exist. Please order as seperates: X-Q225-WS and X-MQ or X-DQ. | G41: =IF(F41-F41*$G$17=0,"",F41-F41*$G$17) | H41: =IFERROR(G41*$H$17,"") | I41: =IFERROR(ROUND(H41*$I$17,0),"") | J41: =IFERROR((I41-H41)/I41,"")
B42: A system discount will be applied to the Rack to ensure the System price remains the same. | G42: =IF(F42-F42*$G$17=0,"",F42-F42*$G$17) | H42: =IFERROR(G42*$H$17,"") | I42: =IFERROR(ROUND(H42*$I$17,0),"") | J42: =IFERROR((I42-H42)/I42,"")
G43: =IF(F43-F43*$G$17=0,"",F43-F43*$G$17) | H43: =IFERROR(G43*$H$17,"") | I43: =IFERROR(ROUND(H43*$I$17,0),"") | J43: =IFERROR((I43-H43)/I43,"")
A44: DiGiCo Quantum 225 Surface | G44: =IF(F44-F44*$G$17=0,"",F44-F44*$G$17) | H44: =IFERROR(G44*$H$17,"") | I44: =IFERROR(ROUND(H44*$I$17,0),"") | J44: =IFERROR((I44-H44)/I44,"")
G45: =IF(F45-F45*$G$17=0,"",F45-F45*$G$17) | H45: =IFERROR(G45*$H$17,"") | I45: =IFERROR(ROUND(H45*$I$17,0),"") | J45: =IFERROR((I45-H45)/I45,"")
A46: X-Q225-WS-DS | B46: DiGiCo Quantum 225 dual screen surface | E46: =ROUND(F46/0.55,0) -> 35636 | F46: 19600 | G46: =IF(F46-F46*25%=0,"",F46-F46*25%) -> 14700 | H46: =IFERROR(G46*$H$17,"") -> 2160900 | I46: =IFERROR(ROUND(H46*$I$17,0),"") -> 3068478 | J46: =IFERROR((I46-H46)/I46,"") -> 0.29577465
...

Sheet Q 852
B1: DiGiCo Quantum 852 Distributor Price List
B3: Sept 2024
B5: Unit 10 Silverglade Business Park, Leatherhead Road
B6: Chessington, Surrey, KT9 2QL
B7: Tel; +44 1372 845600
B8: Fax; +44 1372 845656
B9: email; sales@digiconsoles.com
B10: web; www.digiconsoles.com
B12: FCA Glenrothes KY7 4NX. E&OE. Prices, Products and Specification are subject to change without notice.
B13: This price list supercedes all previous price lists
A15: Product Code | B15: Description | E15: List (£) | F15: Distributor (£) | G15: Disc. () | H15: HT Buy (INR) | I15: Customer Price | J15: Hi-Tech
G16: 0.2 | H16: 147 | I16: 1.42 | J16: Margin
A17: DiGiCo Quantum 852 32bit System
B19: DiGiCo Quantum 852 32bit touring system | E19: =ROUND(F19/0.55,0) -> 219804 | F19: 120892.38 | G19: =IF(F19-F19*$G$16=0,"",F19-F19*$G$16) -> 96713.904 | H19: =IFERROR(G19*$H$16,"") -> 14216944 | I19: =IFERROR(ROUND(H19*$I$16,0),"") -> 20188060 | J19: =IFERROR((I19-H19)/I19,"") -> 0.29577464
B20: 1 x Quantum 852 surface - 36+2+2 100mm faders, 12 60mm faders, 2 quantum engines, HMA optics, 2 DMI slots, 8 BNC MADI, 2 PSU, 32 GPI/O | G20: =IF(F20-F20*$G$16=0,"",F20-F20*$G$16) | H20: =IFERROR(G20*$H$16,"") | I20: =IFERROR(ROUND(H20*$I$16,0),"") | J20: =IFERROR((I20-H20)/I20,"")
B21: 384 input channels, 192 output busses, 2 mono or stereo solo busses. LR, LCR, LCRS or 5.1 master buss | G21: =IF(F21-F21*$G$16=0,"",F21-F21*$G$16) | H21: =IFERROR(G21*$H$16,"") | I21: =IFERROR(ROUND(H21*$I$16,0),"") | J21: =IFERROR((I21-H21)/I21,"")
B22: 64ch plugin I/O (Fourier or Waves), 64 x 64 matrix, 36 CG/VCA, 64 FX (Max 32 Reverbs), 48 x 32 band graphic eq’s, | G22: =IF(F22-F22*$G$16=0,"",F22-F22*$G$16) | H22: =IFERROR(G22*$H$16,"") | I22: =IFERROR(ROUND(H22*$I$16,0),"") | J22: =IFERROR((I22-H22)/I22,"")
B23: 384 Nodal Processors, 128 Mustard Processors, 32 Spice FX | G23: =IF(F23-F23*$G$16=0,"",F23-F23*$G$16) | H23: =IFERROR(G23*$H$16,"") | I23: =IFERROR(ROUND(H23*$I$16,0),"") | J23: =IFERROR((I23-H23)/I23,"")
B24: Local I/O 12 x 32bit Mic inputs, 12 x 32bit Line outputs, 12 x AES I/O mono stream, dust cover | G24: =IF(F24-F24*$G$16=0,"",F24-F24*$G$16) | H24: =IFERROR(G24*$H$16,"") | I24: =IFERROR(ROUND(H24*$I$16,0),"") | J24: =IFERROR((I24-H24)/I24,"")
B25: 1 x Stage SD-Rack, HMA optics, 2 BNC MADI, dual PSU - 56 32bit mic/line in / 40 32bit line out / 16 AES outputs | G25: =IF(F25-F25*$G$16=0,"",F25-F25*$G$16) | H25: =IFERROR(G25*$H$16,"") | I25: =IFERROR(ROUND(H25*$I$16,0),"") | J25: =IFERROR((I25-H25)/I25,"")
B26: 2 x 150m optical cable on drum | G26: =IF(F26-F26*$G$16=0,"",F26-F26*$G$16) | H26: =IFERROR(G26*$H$16,"") | I26: =IFERROR(ROUND(H26*$I$16,0),"") | J26: =IFERROR((I26-H26)/I26,"")
B27: 1 x Touring surface flight case | G27: =IF(F27-F27*$G$16=0,"",F27-F27*$G$16) | H27: =IFERROR(G27*$H$16,"") | I27: =IFERROR(ROUND(H27*$I$16,0),"") | J27: =IFERROR((I27-H27)/I27,"")
G28: =IF(F28-F28*$G$16=0,"",F28-F28*$G$16) | H28: =IFERROR(G28*$H$16,"") | I28: =IFERROR(ROUND(H28*$I$16,0),"") | J28: =IFERROR((I28-H28)/I28,"")
A29: DiGiCo Quantum 852 Surface | G29: =IF(F29-F29*$G$16=0,"",F29-F29*$G$16) | H29: =IFERROR(G29*$H$16,"") | I29: =IFERROR(ROUND(H29*$I$16,0),"") | J29: =IFERROR((I29-H29)/I29,"")
G30: =IF(F30-F30*$G$16=0,"",F30-F30*$G$16) | H30: =IFERROR(G30*$H$16,"") | I30: =IFERROR(ROUND(H30*$I$16,0),"") | J30: =IFERROR((I30-H30)/I30,"")
A31: X-Q852-WS-OP | B31: DiGiCo Quantum 852 surface - MADI / HMA optics | E31: =ROUND(F31/0.55,0) -> 178091 | F31: 97950 | G31: =IF(F31-F31*$G$16=0,"",F31-F31*$G$16) -> 78360 | H31: =IFERROR(G31*$H$16,"") -> 11518920 | I31: =IFERROR(ROUND(H31*$I$16,0),"") -> 16356866 | J31: =IFERROR((I31-H31)/I31,"") -> 0.29577463
B32: 1 x Quantum 852 surface - 36+2+2 100mm faders, 12 60mm faders, 2 quantum engines, HMA optics, 2 DMI slots, 8 BNC MADI, 2 PSU, 32 GPI/O | G32: =IF(F32-F32*$G$16=0,"",F32-F32*$G$16) | H32: =IFERROR(G32*$H$16,"") | I32: =IFERROR(ROUND(H32*$I$16,0),"") | J32: =IFERROR((I32-H32)/I32,"")
B33: 384 input channels, 192 output busses, 2 mono or stereo solo busses. LR, LCR, LCRS or 5.1 master buss | G33: =IF(F33-F33*$G$16=0,"",F33-F33*$G$16) | H33: =IFERROR(G33*$H$16,"") | I33: =IFERROR(ROUND(H33*$I$16,0),"") | J33: =IFERROR((I33-H33)/I33,"")
B34: 64 x 64 matrix, 36 CG/VCA, 64 FX (Max 32 Reverbs), 48 x 32 band graphic eq’s, | G34: =IF(F34-F34*$G$16=0,"",F34-F34*$G$16) | H34: =IFERROR(G34*$H$16,"") | I34: =IFERROR(ROUND(H34*$I$16,0),"") | J34: =IFERROR((I34-H34)/I34,"")
B35: 384 Nodal Processors, 128 Mustard Processors, 32 Spice FX | G35: =IF(F35-F35*$G$16=0,"",F35-F35*$G$16) | H35: =IFERROR(G35*$H$16,"") | I35: =IFERROR(ROUND(H35*$I$16,0),"") | J35: =IFERROR((I35-H35)/I35,"")
B36: Local I/O 12 x 32bit Mic inputs, 12 x 32bit Line outputs, 12 x AES I/O mono stream, dust cover | G36: =IF(F36-F36*$G$16=0,"",F36-F36*$G$16) | H36: =IFERROR(G36*$H$16,"") | I36: =IFERROR(ROUND(H36*$I$16,0),"") | J36: =IFERROR((I36-H36)/I36,"")
B37: Dimensions; 1767(w) x 1075(d) x 607(h) mm Weight; 120Kg | G37: =IF(F37-F37*$G$16=0,"",F37-F37*$G$16) | H37: =IFERROR(G37*$H$16,"") | I37: =IFERROR(ROUND(H37*$I$16,0),"") | J37: =IFERROR((I37-H37)/I37,"")
G38: =IF(F38-F38*$G$16=0,"",F38-F38*$G$16) | H38: =IFERROR(G38*$H$16,"") | I38: =IFERROR(ROUND(H38*$I$16,0),"") | J38: =IFERROR((I38-H38)/I38,"")
A39: X-Q852-WS-NC | B39: DiGiCo Quantum 852 surface - MADI / NC optics | E39: =ROUND(F39/0.55,0) -> 175865 | F39: 96726 | G39: =IF(F39-F39*$G$16=0,"",F39-F39*$G$16) -> 77380.8 | H39: =IFERROR(G39*$H$16,"") -> 11374978 | I39: =IFERROR(ROUND(H39*$I$16,0),"") -> 16152468 | J39: =IFERROR((I39-H39)/I39,"") -> 0.29577464
B40: 1 x Quantum 852 surface - 36+2+2 100mm faders, 12 60mm faders, 2 quantum engines, NC optics, 2 DMI slots, 8 BNC MADI, 2 PSU, 32 GPI/O | G40: =IF(F40-F40*$G$16=0,"",F40-F40*$G$16) | H40: =IFERROR(G40*$H$16,"") | I40: =IFERROR(ROUND(H40*$I$16,0),"") | J40: =IFERROR((I40-H40)/I40,"")
B41: 384 input channels, 192 output busses, 2 mono or stereo solo busses. LR, LCR, LCRS or 5.1 master buss | G41: =IF(F41-F41*$G$16=0,"",F41-F41*$G$16) | H41: =IFERROR(G41*$H$16,"") | I41: =IFERROR(ROUND(H41*$I$16,0),"") | J41: =IFERROR((I41-H41)/I41,"")
B42: 64 x 64 matrix, 36 CG/VCA, 64 FX (Max 32 Reverbs), 48 x 32 band graphic eq’s, | G42: =IF(F42-F42*$G$16=0,"",F42-F42*$G$16) | H42: =IFERROR(G42*$H$16,"") | I42: =IFERROR(ROUND(H42*$I$16,0),"") | J42: =IFERROR((I42-H42)/I42,"")
B43: 384 Nodal Processors, 128 Mustard Processors, 32 Spice FX | G43: =IF(F43-F43*$G$16=0,"",F43-F43*$G$16) | H43: =IFERROR(G43*$H$16,"") | I43: =IFERROR(ROUND(H43*$I$16,0),"") | J43: =IFERROR((I43-H43)/I43,"")
B44: Local I/O 12 x 32bit Mic inputs, 12 x 32bit Line outputs, 12 x AES I/O mono stream, dust cover | G44: =IF(F44-F44*$G$16=0,"",F44-F44*$G$16) | H44: =IFERROR(G44*$H$16,"") | I44: =IFERROR(ROUND(H44*$I$16,0),"") | J44: =IFERROR((I44-H44)/I44,"")
B45: Dimensions; 1767(w) x 1075(d) x 607(h) mm Weight; 120Kg | G45: =IF(F45-F45*$G$16=0,"",F45-F45*$G$16) | H45: =IFERROR(G45*$H$16,"") | I45: =IFERROR(ROUND(H45*$I$16,0),"") | J45: =IFERROR((I45-H45)/I45,"")
...

Sheet Solutions
B1: DiGiCo Solutions Distributor Price List
B3: Sept 2024
B6: Unit 10 Silverglade Business Park, Leatherhead Road
B7: Chessington, Surrey, KT9 2QL
B8: Tel; +44 1372 845600
B9: Fax; +44 1372 845656
B10: email; sales@digiconsoles.com
B11: web; www.digiconsoles.com
B13: FCA Glenrothes KY7 4NX. E&OE. Prices, Products and Specification are subject to change without notice.
B14: This price list supercedes all previous price lists.
A16: Product Code | B16: Description | E16: List (£) | F16: Distributor (£) | G16: Disc. () | H16: HT Buy (INR) | I16: Customer Price | J16: Hi-Tech
H17: 147 | I17: 1.42 | J17: Margin
A18: DiGiCo Interface Boxes
A20: X-LRB | B20: DiGiCo Little Red Box | E20: =ROUND(F20/0.55,0) -> 817 | F20: 449.1 | G20: =IF(F20-F20*0%=0,"",F20-F20*0%) -> 449.1 | H20: =IFERROR(G20*$H$17,"") -> 66017.7 | I20: =IFERROR(ROUND(H20*$I$17,0),"") -> 93745 | J20: =IFERROR((I20-H20)/I20,"") -> 0.29577364
B21: Interface box. Includes 2m CAT5e cable and 2m USB cable | G21: =IF(F21-F21*0%=0,"",F21-F21*0%) | H21: =IFERROR(G21*$H$17,"") | I21: =IFERROR(ROUND(H21*$I$17,0),"") | J21: =IFERROR((I21-H21)/I21,"")
G22: =IF(F22-F22*0%=0,"",F22-F22*0%) | H22: =IFERROR(G22*$H$17,"") | I22: =IFERROR(ROUND(H22*$I$17,0),"") | J22: =IFERROR((I22-H22)/I22,"")
A23: X-LBB | B23: DiGiCo Little Blue Box | E23: =ROUND(F23/0.55,0) -> 817 | F23: 449.1 | G23: =IF(F23-F23*0%=0,"",F23-F23*0%) -> 449.1 | H23: =IFERROR(G23*$H$17,"") -> 66017.7 | I23: =IFERROR(ROUND(H23*$I$17,0),"") -> 93745 | J23: =IFERROR((I23-H23)/I23,"") -> 0.29577364
B24: Interface box. Includes 2m CAT5e cable and 2m USB cable | G24: =IF(F24-F24*0%=0,"",F24-F24*0%) | H24: =IFERROR(G24*$H$17,"") | I24: =IFERROR(ROUND(H24*$I$17,0),"") | J24: =IFERROR((I24-H24)/I24,"")
G25: =IF(F25-F25*0%=0,"",F25-F25*0%) | H25: =IFERROR(G25*$H$17,"") | I25: =IFERROR(ROUND(H25*$I$17,0),"") | J25: =IFERROR((I25-H25)/I25,"")
A26: MOD-LB-2U | B26: DiGiCo Rack Kit for two Little Box's (2U) | E26: =ROUND(F26/0.55,0) -> 44 | F26: 24.3 | G26: =IF(F26-F26*0%=0,"",F26-F26*0%) -> 24.3 | H26: =IFERROR(G26*$H$17,"") -> 3572.1 | I26: =IFERROR(ROUND(H26*$I$17,0),"") -> 5072 | J26: =IFERROR((I26-H26)/I26,"") -> 0.29572161
B27: Includes blank panel | G27: =IF(F27-F27*0%=0,"",F27-F27*0%) | H27: =IFERROR(G27*$H$17,"") | I27: =IFERROR(ROUND(H27*$I$17,0),"") | J27: =IFERROR((I27-H27)/I27,"")
G28: =IF(F28-F28*0%=0,"",F28-F28*0%) | H28: =IFERROR(G28*$H$17,"") | I28: =IFERROR(ROUND(H28*$I$17,0),"") | J28: =IFERROR((I28-H28)/I28,"")
A29: X-PB-OP | B29: DiGiCo Purple Box - Multimode HMA | E29: =ROUND(F29/0.55,0) -> 2700 | F29: 1485 | G29: =IF(F29-F29*0%=0,"",F29-F29*0%) -> 1485 | H29: =IFERROR(G29*$H$17,"") -> 218295 | I29: =IFERROR(ROUND(H29*$I$17,0),"") -> 309979 | J29: =IFERROR((I29-H29)/I29,"") -> 0.29577488
B30: 1U. 2 x MADI-Optical bi-directional converter. BNC & etherCON MADI / HMA. Dual PSU. Multimode Optics | G30: =IF(F30-F30*0%=0,"",F30-F30*0%) | H30: =IFERROR(G30*$H$17,"") | I30: =IFERROR(ROUND(H30*$I$17,0),"") | J30: =IFERROR((I30-H30)/I30,"")
G31: =IF(F31-F31*0%=0,"",F31-F31*0%) | H31: =IFERROR(G31*$H$17,"") | I31: =IFERROR(ROUND(H31*$I$17,0),"") | J31: =IFERROR((I31-H31)/I31,"")
A32: X-PB-NC | B32: DiGiCo Purple Box - Multimode OpticalCON | E32: =ROUND(F32/0.55,0) -> 1718 | F32: 945 | G32: =IF(F32-F32*0%=0,"",F32-F32*0%) -> 945 | H32: =IFERROR(G32*$H$17,"") -> 138915 | I32: =IFERROR(ROUND(H32*$I$17,0),"") -> 197259 | J32: =IFERROR((I32-H32)/I32,"") -> 0.29577358
B33: 1U. 2 x MADI-Optical bi-directional converter. BNC & etherCON MADI / NC. Dual PSU. Multimode Optics | G33: =IF(F33-F33*0%=0,"",F33-F33*0%) | H33: =IFERROR(G33*$H$17,"") | I33: =IFERROR(ROUND(H33*$I$17,0),"") | J33: =IFERROR((I33-H33)/I33,"")
G34: =IF(F34-F34*0%=0,"",F34-F34*0%) | H34: =IFERROR(G34*$H$17,"") | I34: =IFERROR(ROUND(H34*$I$17,0),"") | J34: =IFERROR((I34-H34)/I34,"")
A35: X-PB-ST | B35: DiGiCo Purple Box - Multimode ST | E35: =ROUND(F35/0.55,0) -> 1497 | F35: 823.5 | G35: =IF(F35-F35*0%=0,"",F35-F35*0%) -> 823.5 | H35: =IFERROR(G35*$H$17,"") -> 121054.5 | I35: =IFERROR(ROUND(H35*$I$17,0),"") -> 171897 | J35: =IFERROR((I35-H35)/I35,"") -> 0.29577305
B36: 1U. 2 x MADI-Optical bi-directional converter. BNC & etherCON MADI / ST. Dual PSU. Multimode Optics | G36: =IF(F36-F36*0%=0,"",F36-F36*0%) | H36: =IFERROR(G36*$H$17,"") | I36: =IFERROR(ROUND(H36*$I$17,0),"") | J36: =IFERROR((I36-H36)/I36,"")
G37: =IF(F37-F37*0%=0,"",F37-F37*0%) | H37: =IFERROR(G37*$H$17,"") | I37: =IFERROR(ROUND(H37*$I$17,0),"") | J37: =IFERROR((I37-H37)/I37,"")
A38: X-PB-OP-S | B38: DiGiCo Purple Box - Singlemode HMA | E38: =ROUND(F38/0.55,0) -> 6055 | F38: 3330 | G38: =IF(F38-F38*0%=0,"",F38-F38*0%) -> 3330 | H38: =IFERROR(G38*$H$17,"") -> 489510 | I38: =IFERROR(ROUND(H38*$I$17,0),"") -> 695104 | J38: =IFERROR((I38-H38)/I38,"") -> 0.29577445
B39: 1U. 2 x MADI-Optical bi-directional converter. BNC & etherCON MADI / HMA. Dual PSU. Singlemode Optics | G39: =IF(F39-F39*0%=0,"",F39-F39*0%) | H39: =IFERROR(G39*$H$17,"") | I39: =IFERROR(ROUND(H39*$I$17,0),"") | J39: =IFERROR((I39-H39)/I39,"")
G40: =IF(F40-F40*0%=0,"",F40-F40*0%) | H40: =IFERROR(G40*$H$17,"") | I40: =IFERROR(ROUND(H40*$I$17,0),"") | J40: =IFERROR((I40-H40)/I40,"")
A41: X-PB-NC-S | B41: DiGiCo Purple Box - Singlemode OpticalCON | E41: =ROUND(F41/0.55,0) -> 3845 | F41: 2115 | G41: =IF(F41-F41*0%=0,"",F41-F41*0%) -> 2115 | H41: =IFERROR(G41*$H$17,"") -> 310905 | I41: =IFERROR(ROUND(H41*$I$17,0),"") -> 441485 | J41: =IFERROR((I41-H41)/I41,"") -> 0.29577449
B42: 1U. 2 x MADI-Optical bi-directional converter. BNC & etherCON MADI / NC. Dual PSU. Singlemode Optics | G42: =IF(F42-F42*0%=0,"",F42-F42*0%) | H42: =IFERROR(G42*$H$17,"") | I42: =IFERROR(ROUND(H42*$I$17,0),"") | J42: =IFERROR((I42-H42)/I42,"")
G43: =IF(F43-F43*0%=0,"",F43-F43*0%) | H43: =IFERROR(G43*$H$17,"") | I43: =IFERROR(ROUND(H43*$I$17,0),"") | J43: =IFERROR((I43-H43)/I43,"")
A44: X-PB-ST-S | B44: DiGiCo Purple Box - Singlemode ST | E44: =ROUND(F44/0.55,0) -> 3215 | F44: 1768.5 | G44: =IF(F44-F44*0%=0,"",F44-F44*0%) -> 1768.5 | H44: =IFERROR(G44*$H$17,"") -> 259969.5 | I44: =IFERROR(ROUND(H44*$I$17,0),"") -> 369157 | J44: =IFERROR((I44-H44)/I44,"") -> 0.29577524
B45: 1U. 2 x MADI-Optical bi-directional converter. BNC & etherCON MADI / ST. Dual PSU. Singlemode Optics | G45: =IF(F45-F45*0%=0,"",F45-F45*0%) | H45: =IFERROR(G45*$H$17,"") | I45: =IFERROR(ROUND(H45*$I$17,0),"") | J45: =IFERROR((I45-H45)/I45,"")
J46: =IFERROR((I46-H46)/I46,"")
...

Sheet Racks
B2: DiGiCo Racks, Cards & Cables Distributor Price List
B4: Sept 2024
B6: Unit 10 Silverglade Business Park, Leatherhead Road
B7: Chessington, Surrey, KT9 2QL
B8: Tel; +44 1372 845600
B9: Fax; +44 1372 845656
B10: email; sales@digiconsoles.com
B11: web; www.digiconsoles.com
B13: FCA Glenrothes KY7 4NX. E&OE. Prices, Products and Specification are subject to change without notice.
B14: This price list supercedes all previous price lists.
A16: Product Code | B16: Description | E16: List (£) | F16: Distributor (£) | G16: Disc. () | H16: HT Buy (INR) | I16: Customer Price | J16: Hi-Tech
H17: 147 | I17: 1.42 | J17: Margin
A18: DiGiCo SD-Rack
A20: X-SD-RACK | B20: DiGiCo SD-Rack 192khz (unloaded) | E20: =ROUND(F20/0.55,0) -> 6218 | F20: 3420 | G20: =IF(F20-F20*20%=0,"",F20-F20*20%) -> 2736 | H20: =IFERROR(G20*$H$17,"") -> 402192 | I20: =IFERROR(ROUND(H20*$I$17,0),"") -> 571113 | J20: =IFERROR((I20-H20)/I20,"") -> 0.29577509
B21: 10u Rackframe, 2 PSU's, 14 slots, 2 BNC MADI, 2 Splits, rack kit | G21: =IF(F21-F21*20%=0,"",F21-F21*20%) | H21: =IFERROR(G21*$H$17,"") | I21: =IFERROR(ROUND(H21*$I$17,0),"") | J21: =IFERROR((I21-H21)/I21,"")
B22: 2 x 5m BNC cable, 2 x 100m BNC cable | G22: =IF(F22-F22*20%=0,"",F22-F22*20%) | H22: =IFERROR(G22*$H$17,"") | I22: =IFERROR(ROUND(H22*$I$17,0),"") | J22: =IFERROR((I22-H22)/I22,"")
B23: Dimensions; 483(w) x 444(h) x 371(d) mm Weight; 24Kg | G23: =IF(F23-F23*20%=0,"",F23-F23*20%) | H23: =IFERROR(G23*$H$17,"") | I23: =IFERROR(ROUND(H23*$I$17,0),"") | J23: =IFERROR((I23-H23)/I23,"")
G24: =IF(F24-F24*20%=0,"",F24-F24*20%) | H24: =IFERROR(G24*$H$17,"") | I24: =IFERROR(ROUND(H24*$I$17,0),"") | J24: =IFERROR((I24-H24)/I24,"")
A25: X-SD-RACK-O | B25: DiGiCo SD-Rack 192khz (unloaded) with HMA Optics | E25: =ROUND(F25/0.55,0) -> 9444 | F25: 5194.125 | G25: =IF(F25-F25*20%=0,"",F25-F25*20%) -> 4155.3 | H25: =IFERROR(G25*$H$17,"") -> 610829.1 | I25: =IFERROR(ROUND(H25*$I$17,0),"") -> 867377 | J25: =IFERROR((I25-H25)/I25,"") -> 0.29577439
B26: 10u Rackframe, 2 PSU's, 14 slots, 2 BNC MADI, 2 Splits, 2 HMA optic connections, rack kit | G26: =IF(F26-F26*20%=0,"",F26-F26*20%) | H26: =IFERROR(G26*$H$17,"") | I26: =IFERROR(ROUND(H26*$I$17,0),"") | J26: =IFERROR((I26-H26)/I26,"")
B27: 2 x 5m BNC cable, 2 x 100m BNC cable | G27: =IF(F27-F27*20%=0,"",F27-F27*20%) | H27: =IFERROR(G27*$H$17,"") | I27: =IFERROR(ROUND(H27*$I$17,0),"") | J27: =IFERROR((I27-H27)/I27,"")
B28: Dimensions; 483(w) x 444(h) x 371(d) mm Weight; 24Kg | G28: =IF(F28-F28*20%=0,"",F28-F28*20%) | H28: =IFERROR(G28*$H$17,"") | I28: =IFERROR(ROUND(H28*$I$17,0),"") | J28: =IFERROR((I28-H28)/I28,"")
G29: =IF(F29-F29*20%=0,"",F29-F29*20%) | H29: =IFERROR(G29*$H$17,"") | I29: =IFERROR(ROUND(H29*$I$17,0),"") | J29: =IFERROR((I29-H29)/I29,"")
A30: X-SD-RACK-NC | B30: DiGiCo SD-Rack 192khz (unloaded) with OpticalCON Optics | E30: =ROUND(F30/0.55,0) -> 8331 | F30: 4582.125 | G30: =IF(F30-F30*20%=0,"",F30-F30*20%) -> 3665.7 | H30: =IFERROR(G30*$H$17,"") -> 538857.9 | I30: =IFERROR(ROUND(H30*$I$17,0),"") -> 765178 | J30: =IFERROR((I30-H30)/I30,"") -> 0.29577445
B31: 10u Rackframe, 2 PSU's, 14 slots, 2 BNC MADI, 2 Splits, 2 OpticalCON connections, rack kit | G31: =IF(F31-F31*20%=0,"",F31-F31*20%) | H31: =IFERROR(G31*$H$17,"") | I31: =IFERROR(ROUND(H31*$I$17,0),"") | J31: =IFERROR((I31-H31)/I31,"")
B32: 2 x 5m BNC cable, 2 x 100m BNC cable | G32: =IF(F32-F32*20%=0,"",F32-F32*20%) | H32: =IFERROR(G32*$H$17,"") | I32: =IFERROR(ROUND(H32*$I$17,0),"") | J32: =IFERROR((I32-H32)/I32,"")
B33: Dimensions; 483(w) x 444(h) x 371(d) mm Weight; 24Kg | G33: =IF(F33-F33*20%=0,"",F33-F33*20%) | H33: =IFERROR(G33*$H$17,"") | I33: =IFERROR(ROUND(H33*$I$17,0),"") | J33: =IFERROR((I33-H33)/I33,"")
G34: =IF(F34-F34*20%=0,"",F34-F34*20%) | H34: =IFERROR(G34*$H$17,"") | I34: =IFERROR(ROUND(H34*$I$17,0),"") | J34: =IFERROR((I34-H34)/I34,"")
A35: X-SD-RACK-ST | B35: DiGiCo SD-Rack 192khz (unloaded) with ST Optics | E35: =ROUND(F35/0.55,0) -> 8118 | F35: 4465.125 | G35: =IF(F35-F35*20%=0,"",F35-F35*20%) -> 3572.1 | H35: =IFERROR(G35*$H$17,"") -> 525098.7 | I35: =IFERROR(ROUND(H35*$I$17,0),"") -> 745640 | J35: =IFERROR((I35-H35)/I35,"") -> 0.2957745
B36: 10u Rackframe, 2 PSU's, 14 slots, 2 BNC MADI, 2 Splits, 2 ST optic connections, rack kit | G36: =IF(F36-F36*20%=0,"",F36-F36*20%) | H36: =IFERROR(G36*$H$17,"") | I36: =IFERROR(ROUND(H36*$I$17,0),"") | J36: =IFERROR((I36-H36)/I36,"")
B37: 2 x 5m BNC cable, 2 x 100m BNC cable | G37: =IF(F37-F37*20%=0,"",F37-F37*20%) | H37: =IFERROR(G37*$H$17,"") | I37: =IFERROR(ROUND(H37*$I$17,0),"") | J37: =IFERROR((I37-H37)/I37,"")
B38: Dimensions; 483(w) x 444(h) x 371(d) mm Weight; 24Kg | G38: =IF(F38-F38*20%=0,"",F38-F38*20%) | H38: =IFERROR(G38*$H$17,"") | I38: =IFERROR(ROUND(H38*$I$17,0),"") | J38: =IFERROR((I38-H38)/I38,"")
G39: =IF(F39-F39*20%=0,"",F39-F39*20%) | H39: =IFERROR(G39*$H$17,"") | I39: =IFERROR(ROUND(H39*$I$17,0),"") | J39: =IFERROR((I39-H39)/I39,"")
A40: DiGiCo SD-MINI Rack | E40: =ROUND(F40/0.55,0) -> 0 | G40: =IF(F40-F40*20%=0,"",F40-F40*20%) | H40: =IFERROR(G40*$H$17,"") | I40: =IFERROR(ROUND(H40*$I$17,0),"") | J40: =IFERROR((I40-H40)/I40,"")
G41: =IF(F41-F41*15%=0,"",F41-F41*15%) | H41: =IFERROR(G41*$H$17,"") | I41: =IFERROR(ROUND(H41*$I$17,0),"") | J41: =IFERROR((I41-H41)/I41,"")
A42: X-SDRM-MADI | B42: DiGiCo SD-MINI Rack 192khz (unloaded) | E42: =ROUND(F42/0.55,0) -> 3878 | F42: 2133 | G42: =IF(F42-F42*15%=0,"",F42-F42*15%) -> 1813.05 | H42: =IFERROR(G42*$H$17,"") -> 266518.35 | I42: =IFERROR(ROUND(H42*$I$17,0),"") -> 378456 | J42: =IFERROR((I42-H42)/I42,"") -> 0.29577454
B43: 4u Rackframe, 2 PSU's, 4 slots, 2 BNC MADI, 2 Splits, rack kit, 2 x 5m BNC cable | G43: =IF(F43-F43*15%=0,"",F43-F43*15%) | H43: =IFERROR(G43*$H$17,"") | I43: =IFERROR(ROUND(H43*$I$17,0),"") | J43: =IFERROR((I43-H43)/I43,"")
B44: Dimensions; 483(w) x 177(h) x 408(d) mm Weight; 12Kg | G44: =IF(F44-F44*15%=0,"",F44-F44*15%) | H44: =IFERROR(G44*$H$17,"") | I44: =IFERROR(ROUND(H44*$I$17,0),"") | J44: =IFERROR((I44-H44)/I44,"")
G45: =IF(F45-F45*15%=0,"",F45-F45*15%) | H45: =IFERROR(G45*$H$17,"") | I45: =IFERROR(ROUND(H45*$I$17,0),"") | J45: =IFERROR((I45-H45)/I45,"")
A46: X-SDRM-OP | B46: DiGiCo SD-MINI Rack 192khz (unloaded) with HMA Optics | E46: =ROUND(F46/0.55,0) -> 7102 | F46: 3906 | G46: =IF(F46-F46*15%=0,"",F46-F46*15%) -> 3320.1 | H46: =IFERROR(G46*$H$17,"") -> 488054.7 | I46: =IFERROR(ROUND(H46*$I$17,0),"") -> 693038 | J46: =IFERROR((I46-H46)/I46,"") -> 0.29577498
...

Sheet Klang
B1: KLANG Distributor Price List
B3: Jan 2026
B5: Unit 10 Silverglade Business Park, Leatherhead Road
B6: Chessington, Surrey, KT9 2QL
B7: Tel; +44 1372 845600
B8: Fax; +44 1372 845656
B9: email; sales@digiconsoles.com
B10: web; www.digiconsoles.com
B12: FCA Glenrothes KY7 4PA. E&OE. Prices, Products and Specification are subject to change without notice.
B13: This price list supercedes all previous price lists
A15: Product Code | B15: Description | C15: Insert Picture | E15: Pro User (£) | F15: Distributor (£) | G15: Disc. (%) | H15: HT Buy (INR) | I15: Customer Price | J15: Hi-Tech
G16: 0.1 | H16: 147 | I16: 1.42 | J16: Margin
A17: Klang Konductor Packages
A19: X-KG-KOND-OP | B19: KLANG:konductor 128 input Optocore package (HMA) | E19: =ROUND(F19/0.54,0) -> 12358 | F19: 6673.5 | G19: =IF(F19-F19*$G$16=0,"",F19-F19*$G$16) -> 6006.15 | H19: =IFERROR(G19*$H$16,"") -> 882904.05 | I19: =IFERROR(ROUND(H19*$I$16,0),"") -> 1253724 | J19: =IFERROR((I19-H19)/I19,"") -> 0.29577479
B20: Includes 2 x MOD-DMI-OPTO Optocore DMI cards (HMA connectivity) | G20: =IF(F20-F20*$G$16=0,"",F20-F20*$G$16) | H20: =IFERROR(G20*$H$16,"") | I20: =IFERROR(ROUND(H20*$I$16,0),"") | J20: =IFERROR((I20-H20)/I20,"")
B21: 16 immersive in-ear mixes | G21: =IF(F21-F21*$G$16=0,"",F21-F21*$G$16) | H21: =IFERROR(G21*$H$16,"") | I21: =IFERROR(ROUND(H21*$I$16,0),"") | J21: =IFERROR((I21-H21)/I21,"")
B22: 128 inputs | G22: =IF(F22-F22*$G$16=0,"",F22-F22*$G$16) | H22: =IFERROR(G22*$H$16,"") | I22: =IFERROR(ROUND(H22*$I$16,0),"") | J22: =IFERROR((I22-H22)/I22,"")
B23: Parametric EQ for Inputs & Outputs. Channel tone filter | G23: =IF(F23-F23*$G$16=0,"",F23-F23*$G$16) | H23: =IFERROR(G23*$H$16,"") | I23: =IFERROR(ROUND(H23*$I$16,0),"") | J23: =IFERROR((I23-H23)/I23,"")
B24: Headphone amp with volume control | G24: =IF(F24-F24*$G$16=0,"",F24-F24*$G$16) | H24: =IFERROR(G24*$H$16,"") | I24: =IFERROR(ROUND(H24*$I$16,0),"") | J24: =IFERROR((I24-H24)/I24,"")
B25: 7" touch screen | G25: =IF(F25-F25*$G$16=0,"",F25-F25*$G$16) | H25: =IFERROR(G25*$H$16,"") | I25: =IFERROR(ROUND(H25*$I$16,0),"") | J25: =IFERROR((I25-H25)/I25,"")
B26: 96 kHz | 48 kHz, word clock I/O | G26: =IF(F26-F26*$G$16=0,"",F26-F26*$G$16) | H26: =IFERROR(G26*$H$16,"") | I26: =IFERROR(ROUND(H26*$I$16,0),"") | J26: =IFERROR((I26-H26)/I26,"")
B27: 3 etherCON, RJ45, 2 USB | G27: =IF(F27-F27*$G$16=0,"",F27-F27*$G$16) | H27: =IFERROR(G27*$H$16,"") | I27: =IFERROR(ROUND(H27*$I$16,0),"") | J27: =IFERROR((I27-H27)/I27,"")
B28: 2 PSU | G28: =IF(F28-F28*$G$16=0,"",F28-F28*$G$16) | H28: =IFERROR(G28*$H$16,"") | I28: =IFERROR(ROUND(H28*$I$16,0),"") | J28: =IFERROR((I28-H28)/I28,"")
E29: =ROUND(F29/0.54,0) -> 10006 | F29: 5403.375 | G29: =IF(F29-F29*$G$16=0,"",F29-F29*$G$16) -> 4863.0375 | H29: =IFERROR(G29*$H$16,"") -> 714866.51 | I29: =IFERROR(ROUND(H29*$I$16,0),"") -> 1015110 | J29: =IFERROR((I29-H29)/I29,"") -> 0.29577434
A30: X-KG-KOND-NC | B30: KLANG:konductor 128 input Optocore package (NC) | G30: =IF(F30-F30*$G$16=0,"",F30-F30*$G$16) | H30: =IFERROR(G30*$H$16,"") | I30: =IFERROR(ROUND(H30*$I$16,0),"") | J30: =IFERROR((I30-H30)/I30,"")
B31: Includes 2 x MOD-DMI-NC Optocore DMI cards (OpticalCON connectivity) | G31: =IF(F31-F31*$G$16=0,"",F31-F31*$G$16) | H31: =IFERROR(G31*$H$16,"") | I31: =IFERROR(ROUND(H31*$I$16,0),"") | J31: =IFERROR((I31-H31)/I31,"")
B32: 16 immersive in-ear mixes | G32: =IF(F32-F32*$G$16=0,"",F32-F32*$G$16) | H32: =IFERROR(G32*$H$16,"") | I32: =IFERROR(ROUND(H32*$I$16,0),"") | J32: =IFERROR((I32-H32)/I32,"")
B33: 128 inputs | G33: =IF(F33-F33*$G$16=0,"",F33-F33*$G$16) | H33: =IFERROR(G33*$H$16,"") | I33: =IFERROR(ROUND(H33*$I$16,0),"") | J33: =IFERROR((I33-H33)/I33,"")
B34: Parametric EQ for Inputs & Outputs. Channel tone filter | G34: =IF(F34-F34*$G$16=0,"",F34-F34*$G$16) | H34: =IFERROR(G34*$H$16,"") | I34: =IFERROR(ROUND(H34*$I$16,0),"") | J34: =IFERROR((I34-H34)/I34,"")
B35: Headphone amp with volume control | G35: =IF(F35-F35*$G$16=0,"",F35-F35*$G$16) | H35: =IFERROR(G35*$H$16,"") | I35: =IFERROR(ROUND(H35*$I$16,0),"") | J35: =IFERROR((I35-H35)/I35,"")
B36: 7" touch screen | G36: =IF(F36-F36*$G$16=0,"",F36-F36*$G$16) | H36: =IFERROR(G36*$H$16,"") | I36: =IFERROR(ROUND(H36*$I$16,0),"") | J36: =IFERROR((I36-H36)/I36,"")
B37: 96 kHz | 48 kHz, word clock I/O | G37: =IF(F37-F37*$G$16=0,"",F37-F37*$G$16) | H37: =IFERROR(G37*$H$16,"") | I37: =IFERROR(ROUND(H37*$I$16,0),"") | J37: =IFERROR((I37-H37)/I37,"")
B38: 3 etherCON, RJ45, 2 USB | G38: =IF(F38-F38*$G$16=0,"",F38-F38*$G$16) | H38: =IFERROR(G38*$H$16,"") | I38: =IFERROR(ROUND(H38*$I$16,0),"") | J38: =IFERROR((I38-H38)/I38,"")
B39: 2 PSU | G39: =IF(F39-F39*$G$16=0,"",F39-F39*$G$16) | H39: =IFERROR(G39*$H$16,"") | I39: =IFERROR(ROUND(H39*$I$16,0),"") | J39: =IFERROR((I39-H39)/I39,"")
G40: =IF(F40-F40*$G$16=0,"",F40-F40*$G$16) | H40: =IFERROR(G40*$H$16,"") | I40: =IFERROR(ROUND(H40*$I$16,0),"") | J40: =IFERROR((I40-H40)/I40,"")
A41: X-KG-KOND-ST | B41: KLANG:konductor 128 input Optocore package (ST) | E41: =ROUND(F41/0.54,0) -> 9556 | F41: 5160.375 | G41: =IF(F41-F41*$G$16=0,"",F41-F41*$G$16) -> 4644.3375 | H41: =IFERROR(G41*$H$16,"") -> 682717.61 | I41: =IFERROR(ROUND(H41*$I$16,0),"") -> 969459 | J41: =IFERROR((I41-H41)/I41,"") -> 0.29577464
B42: Includes 2 x MOD-DMI-OPTO Optocore DMI cards (ST connectivity) | G42: =IF(F42-F42*$G$16=0,"",F42-F42*$G$16) | H42: =IFERROR(G42*$H$16,"") | I42: =IFERROR(ROUND(H42*$I$16,0),"") | J42: =IFERROR((I42-H42)/I42,"")
B43: 16 immersive in-ear mixes | G43: =IF(F43-F43*$G$16=0,"",F43-F43*$G$16) | H43: =IFERROR(G43*$H$16,"") | I43: =IFERROR(ROUND(H43*$I$16,0),"") | J43: =IFERROR((I43-H43)/I43,"")
B44: 128 inputs | G44: =IF(F44-F44*$G$16=0,"",F44-F44*$G$16) | H44: =IFERROR(G44*$H$16,"") | I44: =IFERROR(ROUND(H44*$I$16,0),"") | J44: =IFERROR((I44-H44)/I44,"")
B45: Parametric EQ for Inputs & Outputs. Channel tone filter | G45: =IF(F45-F45*$G$16=0,"",F45-F45*$G$16) | H45: =IFERROR(G45*$H$16,"") | I45: =IFERROR(ROUND(H45*$I$16,0),"") | J45: =IFERROR((I45-H45)/I45,"")
...

Sheet Fourier
B1: Fourier Audio Distributor Price List
B3: Jan 2026
B5: Unit 10 Silverglade Business Park, Leatherhead Road
B6: Chessington, Surrey, KT9 2QL
B7: Tel; +44 1372 845600
B8: Fax; +44 1372 845656
B9: email; sales@digiconsoles.com
B10: web; www.digiconsoles.com
B12: FCA Glenrothes KY7 4PA. E&OE. Prices, Products and Specification are subject to change without notice.
B13: This price list supercedes all previous price lists
A15: Product Code | B15: Description | E15: List Price (£) | F15: Distributor (£) | G15: Disc. (%) | H15: HT Buy (INR) | I15: Customer Price | J15: Hi-Tech
G16: 0.1 | H16: 147 | I16: 1.42 | J16: Margin
A17: Fourier Engine
A19: X-FA-TE | B19: Fourier Audio transform.engine | E19: 7273 | F19: 4000 | G19: =IF(F19-F19*$G$16=0,"",F19-F19*$G$16) -> 3600 | H19: =IFERROR(G19*$H$16,"") -> 529200 | I19: =IFERROR(ROUND(H19*$I$16,0),"") -> 751464 | J19: =IFERROR((I19-H19)/I19,"") -> 0.29577465
B20: VST3 plugin host server. | G20: =IF(F20-F20*$G$16=0,"",F20-F20*$G$16) | H20: =IFERROR(G20*$H$16,"") | I20: =IFERROR(ROUND(H20*$I$16,0),"") | J20: =IFERROR((I20-H20)/I20,"")
B21: 2 Dante/ HYPERPORT/ gigaACE/ DX etherCON (primary / secondary). 64ch I/O @ 44.1kHz/48kHz/96kHz. | G21: =IF(F21-F21*$G$16=0,"",F21-F21*$G$16) | H21: =IFERROR(G21*$H$16,"") | I21: =IFERROR(ROUND(H21*$I$16,0),"") | J21: =IFERROR((I21-H21)/I21,"")
B22: 1 etherCON control port. 2 USB (front panel), 4 USB (rear secure bay). 2 PSU. 5 pin din + TCP/IP MIDI. | G22: =IF(F22-F22*$G$16=0,"",F22-F22*$G$16) | H22: =IFERROR(G22*$H$16,"") | I22: =IFERROR(ROUND(H22*$I$16,0),"") | J22: =IFERROR((I22-H22)/I22,"")
B23: Dimensions: 2U. 433(w) x 89(h) x 385(d) mm, Weight: 5.5 kg | G23: =IF(F23-F23*$G$16=0,"",F23-F23*$G$16) | H23: =IFERROR(G23*$H$16,"") | I23: =IFERROR(ROUND(H23*$I$16,0),"") | J23: =IFERROR((I23-H23)/I23,"")
G24: =IF(F24-F24*$G$16=0,"",F24-F24*$G$16) | H24: =IFERROR(G24*$H$16,"") | I24: =IFERROR(ROUND(H24*$I$16,0),"") | J24: =IFERROR((I24-H24)/I24,"")
A25: X-FA-TG | B25: Fourier Audio transform.go | E25: 2800 | F25: 1540 | G25: =IF(F25-F25*$G$16=0,"",F25-F25*$G$16) -> 1386 | H25: =IFERROR(G25*$H$16,"") -> 203742 | I25: =IFERROR(ROUND(H25*$I$16,0),"") -> 289314 | J25: =IFERROR((I25-H25)/I25,"") -> 0.29577552
B26: VST3 plugin host server.
B27: 2 Dante/ HYPERPORT/ gigaACE/ DX etherCON (primary / secondary). 16ch I/O @ 44.1kHz/48kHz/96kHz.
B28: 1 etherCON control port. 1 USB (front panel), 2 USB (rear secure bay). 1 PSU. TCP/IP MIDI.
B29: Dimensions: 2U. 217(w) x 85(h) x 283(d) mm, Weight: 3.7 kg

Sheet Q1
B1: DiGiCo Quantum 112 Distributor Price List
B3: Apr 2026
B5: Unit 10 Silverglade Business Park, Leatherhead Road
B6: Chessington, Surrey, KT9 2QL
B7: Tel; +44 1372 845600
B8: Fax; +44 1372 845656
B9: email; sales@digiconsoles.com
B10: web; www.digiconsoles.com
B12: FCA Glenrothes KY7 4NX. E&OE. Prices, Products and Specification are subject to change without notice.
B13: This price list supercedes all previous price lists.
A15: Product Code | B15: Description | E15: List (£) | F15: Distributor (£) | G15: Disc. (%) | H15: HT Buy (INR) | I15: Customer Price | J15: Hi-Tech
G16: 0 | H16: 147 | I16: 1.42 | J16: Margin
A17: DiGiCo Quantum 225 Systems
A19: X-Q112-MQ | B19: DiGiCo Quantum 112 system - MADI | E19: =ROUND(F19/0.55,0) -> 24545 | F19: 13500 | G19: =IF(F19-F19*$G$16=0,"",F19-F19*$G$16) -> 13500 | H19: =IFERROR(G19*$H$16,"") -> 1984500 | I19: =IFERROR(ROUND(H19*$I$16,0),"") -> 2817990 | J19: =IFERROR((I19-H19)/I19,"") -> 0.29577465
B20: 1 x Quantum 112 surface - 12 faders, 2 DMI slots, Dante 64ch I/O, USB Audio 32ch I/O, 4 BNC MADI | G20: =IF(F20-F20*$G$16=0,"",F20-F20*$G$16) | H20: =IFERROR(G20*$H$16,"") | I20: =IFERROR(ROUND(H20*$I$16,0),"") | J20: =IFERROR((I20-H20)/I20,"")
B21: 80 mono input channels, 24 mono output busses, | G21: =IF(F21-F21*$G$16=0,"",F21-F21*$G$16) | H21: =IFERROR(G21*$H$16,"") | I21: =IFERROR(ROUND(H21*$I$16,0),"") | J21: =IFERROR((I21-H21)/I21,"")
B22: 2 mono or stereo solo busses. LR or LCR master buss | G22: =IF(F22-F22*$G$16=0,"",F22-F22*$G$16) | H22: =IFERROR(G22*$H$16,"") | I22: =IFERROR(ROUND(H22*$I$16,0),"") | J22: =IFERROR((I22-H22)/I22,"")
B23: 12 x 8 matrix, 12 CG/VCA, 8 FX, 12 x 32 band graphic eq’s | G23: =IF(F23-F23*$G$16=0,"",F23-F23*$G$16) | H23: =IFERROR(G23*$H$16,"") | I23: =IFERROR(ROUND(H23*$I$16,0),"") | J23: =IFERROR((I23-H23)/I23,"")
B24: 24 Nodal Processors, 20 Mustard Processors, 6 Spice FX | G24: =IF(F24-F24*$G$16=0,"",F24-F24*$G$16) | H24: =IFERROR(G24*$H$16,"") | I24: =IFERROR(ROUND(H24*$I$16,0),"") | J24: =IFERROR((I24-H24)/I24,"")
B25: Local I/O 16 x Mic/Line inputs, 8 x Line outputs, AES I/O, 2 PSU, 2 GPIO, dust cover, carton | G25: =IF(F25-F25*$G$16=0,"",F25-F25*$G$16) | H25: =IFERROR(G25*$H$16,"") | I25: =IFERROR(ROUND(H25*$I$16,0),"") | J25: =IFERROR((I25-H25)/I25,"")
B26: 1 x Quantum MADI Rack, 2 BNC MADI, dual PSU - 48 mic/line in / up to 24 line out / up to 8 AES output (mono), carton | G26: =IF(F26-F26*$G$16=0,"",F26-F26*$G$16) | H26: =IFERROR(G26*$H$16,"") | I26: =IFERROR(ROUND(H26*$I$16,0),"") | J26: =IFERROR((I26-H26)/I26,"")
B27: 2 x 100m BNC Cables | G27: =IF(F27-F27*$G$16=0,"",F27-F27*$G$16) | H27: =IFERROR(G27*$H$16,"") | I27: =IFERROR(ROUND(H27*$I$16,0),"") | J27: =IFERROR((I27-H27)/I27,"")
G28: =IF(F28-F28*$G$16=0,"",F28-F28*$G$16) | H28: =IFERROR(G28*$H$16,"") | I28: =IFERROR(ROUND(H28*$I$16,0),"") | J28: =IFERROR((I28-H28)/I28,"")
A29: X-Q112-DQ | B29: DiGiCo Quantum 112 system - DANTE | E29: =ROUND(F29/0.55,0) -> 25091 | F29: 13800 | G29: =IF(F29-F29*$G$16=0,"",F29-F29*$G$16) -> 13800 | H29: =IFERROR(G29*$H$16,"") -> 2028600 | I29: =IFERROR(ROUND(H29*$I$16,0),"") -> 2880612 | J29: =IFERROR((I29-H29)/I29,"") -> 0.29577465
B30: 1 x Quantum 112 surface - 12 faders, 2 DMI slots, Dante 64ch I/O, USB Audio 32ch I/O, 4 BNC MADI | G30: =IF(F30-F30*$G$16=0,"",F30-F30*$G$16) | H30: =IFERROR(G30*$H$16,"") | I30: =IFERROR(ROUND(H30*$I$16,0),"") | J30: =IFERROR((I30-H30)/I30,"")
B31: 80 mono input channels, 24 mono output busses, | G31: =IF(F31-F31*$G$16=0,"",F31-F31*$G$16) | H31: =IFERROR(G31*$H$16,"") | I31: =IFERROR(ROUND(H31*$I$16,0),"") | J31: =IFERROR((I31-H31)/I31,"")
B32: 2 mono or stereo solo busses. LR or LCR master buss | G32: =IF(F32-F32*$G$16=0,"",F32-F32*$G$16) | H32: =IFERROR(G32*$H$16,"") | I32: =IFERROR(ROUND(H32*$I$16,0),"") | J32: =IFERROR((I32-H32)/I32,"")
B33: 12 x 8 matrix, 12 CG/VCA, 8 FX, 12 x 32 band graphic eq’s | G33: =IF(F33-F33*$G$16=0,"",F33-F33*$G$16) | H33: =IFERROR(G33*$H$16,"") | I33: =IFERROR(ROUND(H33*$I$16,0),"") | J33: =IFERROR((I33-H33)/I33,"")
B34: 24 Nodal Processors, 20 Mustard Processors, 6 Spice FX | G34: =IF(F34-F34*$G$16=0,"",F34-F34*$G$16) | H34: =IFERROR(G34*$H$16,"") | I34: =IFERROR(ROUND(H34*$I$16,0),"") | J34: =IFERROR((I34-H34)/I34,"")
B35: Local I/O 16 x Mic/Line inputs, 8 x Line outputs, AES I/O, 2 PSU, 2 GPIO, dust cover, carton | G35: =IF(F35-F35*$G$16=0,"",F35-F35*$G$16) | H35: =IFERROR(G35*$H$16,"") | I35: =IFERROR(ROUND(H35*$I$16,0),"") | J35: =IFERROR((I35-H35)/I35,"")
B36: 1 x Quantum Dante Rack, 2 etherCON, dual PSU - 48 mic/line in / up to 24 line out / up to 8 AES output (mono), carton | G36: =IF(F36-F36*$G$16=0,"",F36-F36*$G$16) | H36: =IFERROR(G36*$H$16,"") | I36: =IFERROR(ROUND(H36*$I$16,0),"") | J36: =IFERROR((I36-H36)/I36,"")
B37: 1 x 75m CAT6 Cable | G37: =IF(F37-F37*$G$16=0,"",F37-F37*$G$16) | H37: =IFERROR(G37*$H$16,"") | I37: =IFERROR(ROUND(H37*$I$16,0),"") | J37: =IFERROR((I37-H37)/I37,"")
G38: =IF(F38-F38*$G$16=0,"",F38-F38*$G$16) | H38: =IFERROR(G38*$H$16,"") | I38: =IFERROR(ROUND(H38*$I$16,0),"") | J38: =IFERROR((I38-H38)/I38,"")
A39: DiGiCo Quantum 225 Surface | G39: =IF(F39-F39*$G$16=0,"",F39-F39*$G$16) | H39: =IFERROR(G39*$H$16,"") | I39: =IFERROR(ROUND(H39*$I$16,0),"") | J39: =IFERROR((I39-H39)/I39,"")
G40: =IF(F40-F40*$G$16=0,"",F40-F40*$G$16) | H40: =IFERROR(G40*$H$16,"") | I40: =IFERROR(ROUND(H40*$I$16,0),"") | J40: =IFERROR((I40-H40)/I40,"")
A41: X-Q112-WS | B41: DiGiCo Quantum 112 surface | E41: =ROUND(F41/0.55,0) -> 17455 | F41: 9600 | G41: =IF(F41-F41*$G$16=0,"",F41-F41*$G$16) -> 9600 | H41: =IFERROR(G41*$H$16,"") -> 1411200 | I41: =IFERROR(ROUND(H41*$I$16,0),"") -> 2003904 | J41: =IFERROR((I41-H41)/I41,"") -> 0.29577465
B42: Quantum 112 surface - 12 faders, 2 DMI slots, Dante 64ch I/O, USB Audio 32ch I/O, 4 BNC MADI | G42: =IF(F42-F42*$G$16=0,"",F42-F42*$G$16) | H42: =IFERROR(G42*$H$16,"") | I42: =IFERROR(ROUND(H42*$I$16,0),"") | J42: =IFERROR((I42-H42)/I42,"")
B43: 80 mono input channels, 24 mono output busses, | G43: =IF(F43-F43*$G$16=0,"",F43-F43*$G$16) | H43: =IFERROR(G43*$H$16,"") | I43: =IFERROR(ROUND(H43*$I$16,0),"") | J43: =IFERROR((I43-H43)/I43,"")
B44: 2 mono or stereo solo busses. LR or LCR master buss | G44: =IF(F44-F44*$G$16=0,"",F44-F44*$G$16) | H44: =IFERROR(G44*$H$16,"") | I44: =IFERROR(ROUND(H44*$I$16,0),"") | J44: =IFERROR((I44-H44)/I44,"")
B45: 12 x 8 matrix, 12 CG/VCA, 8 FX, 12 x 32 band graphic eq’s | G45: =IF(F45-F45*$G$16=0,"",F45-F45*$G$16) | H45: =IFERROR(G45*$H$16,"") | I45: =IFERROR(ROUND(H45*$I$16,0),"") | J45: =IFERROR((I45-H45)/I45,"")
...

Sheet Q 3
B1: DiGiCo Quantum 3 Distributor Price List
B3: Sept 2024
B5: Unit 10 Silverglade Business Park, Leatherhead Road | F5: Pound considered @ INR 127.5
B6: Chessington, Surrey, KT9 2QL
B7: Tel; +44 1372 845600
B8: Fax; +44 1372 845656 | F8: Freight @ 2.5%
B9: email; sales@digiconsoles.com | F9: Custom @ 8.5%
B10: web; www.digiconsoles.com | F10: Clearance @ 1%
B12: FCA Glenrothes KY7 4NX. E&OE. Prices, Products and Specification are subject to change without notice.
B13: This price list supercedes all previous price lists
A15: Product Code | B15: Description | E15: List (£) | F15: Distributor (£) | G15: Disc. (20%) | H15: HT Buy (INR) | I15: Customer Price | J15: Hi-Tech
G16: 0.2 | H16: 147 | I16: 1.42 | J16: Margin
A17: DiGiCo Quantum 338 32bit System
B19: DiGiCo Quantum 338 system | E19: =ROUND(F19/0.55,0) -> 97867 | F19: 53826.75 | G19: =IF(F19-F19*$G$16=0,"",F19-F19*$G$16) -> 43061.4 | H19: =IFERROR(G19*$H$16,"") -> 6330025.8 | I19: =IFERROR(ROUND(H19*$I$16,0),"") -> 8988637 | J19: =IFERROR((I19-H19)/I19,"") -> 0.29577468
B20: 1 x Quantum 338 surface - 36+2 faders, HMA optics, 2 DMI slots, USB Audio I/O, 6 BNC MADI, 2 PSU, 16 GPIO | G20: =IF(F20-F20*$G$16=0,"",F20-F20*$G$16) | H20: =IFERROR(G20*$H$16,"") | I20: =IFERROR(ROUND(H20*$I$16,0),"") | J20: =IFERROR((I20-H20)/I20,"")
B21: 128 mono input channels, 64 mono output busses, | G21: =IF(F21-F21*$G$16=0,"",F21-F21*$G$16) | H21: =IFERROR(G21*$H$16,"") | I21: =IFERROR(ROUND(H21*$I$16,0),"") | J21: =IFERROR((I21-H21)/I21,"")
B22: 2 mono or stereo solo busses. LR or LCR master buss | G22: =IF(F22-F22*$G$16=0,"",F22-F22*$G$16) | H22: =IFERROR(G22*$H$16,"") | I22: =IFERROR(ROUND(H22*$I$16,0),"") | J22: =IFERROR((I22-H22)/I22,"")
B23: 24 x 24 matrix, 24 CG/VCA, 24 FX, 24 x 32 band graphic eq’s, | G23: =IF(F23-F23*$G$16=0,"",F23-F23*$G$16) | H23: =IFERROR(G23*$H$16,"") | I23: =IFERROR(ROUND(H23*$I$16,0),"") | J23: =IFERROR((I23-H23)/I23,"")
B24: 64 Nodal Processors, 36 Mustard Processors, 8 Spice FX | G24: =IF(F24-F24*$G$16=0,"",F24-F24*$G$16) | H24: =IFERROR(G24*$H$16,"") | I24: =IFERROR(ROUND(H24*$I$16,0),"") | J24: =IFERROR((I24-H24)/I24,"")
B25: Local I/O 8 x 32bit Mic/Line inputs, 8 x 32bit Line outputs, 8 x AES I/O mono stream, dust cover, carton | G25: =IF(F25-F25*$G$16=0,"",F25-F25*$G$16) | H25: =IFERROR(G25*$H$16,"") | I25: =IFERROR(ROUND(H25*$I$16,0),"") | J25: =IFERROR((I25-H25)/I25,"")
B26: 1 x Stage SD-Rack, HMA optics, 2 BNC MADI, dual PSU - 56 32bit mic/line in / 40 32bit line out / 16 AES outputs | G26: =IF(F26-F26*$G$16=0,"",F26-F26*$G$16) | H26: =IFERROR(G26*$H$16,"") | I26: =IFERROR(ROUND(H26*$I$16,0),"") | J26: =IFERROR((I26-H26)/I26,"")
B27: 2 x 150m optical cable on drum | G27: =IF(F27-F27*$G$16=0,"",F27-F27*$G$16) | H27: =IFERROR(G27*$H$16,"") | I27: =IFERROR(ROUND(H27*$I$16,0),"") | J27: =IFERROR((I27-H27)/I27,"")
G28: =IF(F28-F28*$G$16=0,"",F28-F28*$G$16) | H28: =IFERROR(G28*$H$16,"") | I28: =IFERROR(ROUND(H28*$I$16,0),"") | J28: =IFERROR((I28-H28)/I28,"")
A29: DiGiCo Quantum 3 Surfaces | G29: =IF(F29-F29*$G$16=0,"",F29-F29*$G$16) | H29: =IFERROR(G29*$H$16,"") | I29: =IFERROR(ROUND(H29*$I$16,0),"") | J29: =IFERROR((I29-H29)/I29,"")
G30: =IF(F30-F30*$G$16=0,"",F30-F30*$G$16) | H30: =IFERROR(G30*$H$16,"") | I30: =IFERROR(ROUND(H30*$I$16,0),"") | J30: =IFERROR((I30-H30)/I30,"")
A31: X-Q338-WS | B31: DiGiCo Quantum 338 surface | E31: =ROUND(F31/0.55,0) -> 57426 | F31: 31584.375 | G31: =IF(F31-F31*$G$16=0,"",F31-F31*$G$16) -> 25267.5 | H31: =IFERROR(G31*$H$16,"") -> 3714322.5 | I31: =IFERROR(ROUND(H31*$I$16,0),"") -> 5274338 | J31: =IFERROR((I31-H31)/I31,"") -> 0.29577465
B32: Quantum 338 surface - 36+2 faders, 2 DMI slots, USB Audio I/O, 6 BNC MADI, 2 PSU, 16 GPIO | G32: =IF(F32-F32*$G$16=0,"",F32-F32*$G$16) | H32: =IFERROR(G32*$H$16,"") | I32: =IFERROR(ROUND(H32*$I$16,0),"") | J32: =IFERROR((I32-H32)/I32,"")
B33: 128 mono input channels, 64 mono output busses, | G33: =IF(F33-F33*$G$16=0,"",F33-F33*$G$16) | H33: =IFERROR(G33*$H$16,"") | I33: =IFERROR(ROUND(H33*$I$16,0),"") | J33: =IFERROR((I33-H33)/I33,"")
B34: 2 mono or stereo solo busses. LR or LCR master buss | G34: =IF(F34-F34*$G$16=0,"",F34-F34*$G$16) | H34: =IFERROR(G34*$H$16,"") | I34: =IFERROR(ROUND(H34*$I$16,0),"") | J34: =IFERROR((I34-H34)/I34,"")
B35: 24 x 24 matrix, 24 CG/VCA, 24 FX, 24 x 32 band graphic eq’s, | G35: =IF(F35-F35*$G$16=0,"",F35-F35*$G$16) | H35: =IFERROR(G35*$H$16,"") | I35: =IFERROR(ROUND(H35*$I$16,0),"") | J35: =IFERROR((I35-H35)/I35,"")
B36: 64 Nodal Processors, 36 Mustard Processors, 8 Spice FX | G36: =IF(F36-F36*$G$16=0,"",F36-F36*$G$16) | H36: =IFERROR(G36*$H$16,"") | I36: =IFERROR(ROUND(H36*$I$16,0),"") | J36: =IFERROR((I36-H36)/I36,"")
B37: Local I/O 8 x 32bit Mic/Line inputs, 8 x 32bit Line outputs, 8 x AES I/O mono stream, dust cover, carton | G37: =IF(F37-F37*$G$16=0,"",F37-F37*$G$16) | H37: =IFERROR(G37*$H$16,"") | I37: =IFERROR(ROUND(H37*$I$16,0),"") | J37: =IFERROR((I37-H37)/I37,"")
B38: Dimensions; 1595(w) x 805(d) x 482(h) mm Weight; 66kg | G38: =IF(F38-F38*$G$16=0,"",F38-F38*$G$16) | H38: =IFERROR(G38*$H$16,"") | I38: =IFERROR(ROUND(H38*$I$16,0),"") | J38: =IFERROR((I38-H38)/I38,"")
G39: =IF(F39-F39*$G$16=0,"",F39-F39*$G$16) | H39: =IFERROR(G39*$H$16,"") | I39: =IFERROR(ROUND(H39*$I$16,0),"") | J39: =IFERROR((I39-H39)/I39,"")
A40: X-Q338-WS-OP | B40: DiGiCo Quantum 338 surface - HMA optics | E40: =ROUND(F40/0.55,0) -> 64790 | F40: 35634.375 | G40: =IF(F40-F40*$G$16=0,"",F40-F40*$G$16) -> 28507.5 | H40: =IFERROR(G40*$H$16,"") -> 4190602.5 | I40: =IFERROR(ROUND(H40*$I$16,0),"") -> 5950656 | J40: =IFERROR((I40-H40)/I40,"") -> 0.2957747
B41: Quantum 338 surface - 36+2 faders, HMA optics, 2 DMI slots, USB Audio I/O, 6 BNC MADI, 2 PSU, 16 GPIO | G41: =IF(F41-F41*$G$16=0,"",F41-F41*$G$16) | H41: =IFERROR(G41*$H$16,"") | I41: =IFERROR(ROUND(H41*$I$16,0),"") | J41: =IFERROR((I41-H41)/I41,"")
B42: 128 mono input channels, 64 mono output busses, | G42: =IF(F42-F42*$G$16=0,"",F42-F42*$G$16) | H42: =IFERROR(G42*$H$16,"") | I42: =IFERROR(ROUND(H42*$I$16,0),"") | J42: =IFERROR((I42-H42)/I42,"")
B43: 2 mono or stereo solo busses. LR or LCR master buss | G43: =IF(F43-F43*$G$16=0,"",F43-F43*$G$16) | H43: =IFERROR(G43*$H$16,"") | I43: =IFERROR(ROUND(H43*$I$16,0),"") | J43: =IFERROR((I43-H43)/I43,"")
B44: 24 x 24 matrix, 24 CG/VCA, 24 FX, 24 x 32 band graphic eq’s, | G44: =IF(F44-F44*$G$16=0,"",F44-F44*$G$16) | H44: =IFERROR(G44*$H$16,"") | I44: =IFERROR(ROUND(H44*$I$16,0),"") | J44: =IFERROR((I44-H44)/I44,"")
B45: 64 Nodal Processors, 36 Mustard Processors, 8 Spice FX | G45: =IF(F45-F45*$G$16=0,"",F45-F45*$G$16) | H45: =IFERROR(G45*$H$16,"") | I45: =IFERROR(ROUND(H45*$I$16,0),"") | J45: =IFERROR((I45-H45)/I45,"")
...

Sheet Q 5
B1: DiGiCo Quantum 5 Distributor Price List
B3: Sept 2024
B5: Unit 10 Silverglade Business Park, Leatherhead Road
B6: Chessington, Surrey, KT9 2QL
B7: Tel; +44 1372 845600
B8: Fax; +44 1372 845656
B9: email; sales@digiconsoles.com
B10: web; www.digiconsoles.com
B12: FCA Glenrothes KY7 4NX. E&OE. Prices, Products and Specification are subject to change without notice.
B13: This price list supercedes all previous price lists.
A15: Product Code | B15: Description | E15: List (£) | F15: Distributor (£) | G15: Disc. | H15: HT Buy (INR) | I15: Customer Price | J15: Hi-Tech
G16: 0 | H16: 147 | I16: 1.42 | J16: Margin
A17: DiGiCo Quantum 5 32Bit System
B19: DiGiCo Quantum 5 32bit touring system | E19: =ROUND(F19/0.55,0) -> 144627 | F19: 79544.88 | G19: =IF(F19-F19*$G$16=0,"",F19-F19*$G$16) -> 79544.88 | H19: =IFERROR(G19*$H$16,"") -> 11693097 | I19: =IFERROR(ROUND(H19*$I$16,0),"") -> 16604198 | J19: =IFERROR((I19-H19)/I19,"") -> 0.29577464
B20: 1 x Quantum 5 surface - 36+1 faders, HMA optics, 2 DMI slots, USB Audio I/O, 8 BNC MADI, 2 PSU, 16 GPI/O | G20: =IF(F20-F20*$G$16=0,"",F20-F20*$G$16) | H20: =IFERROR(G20*$H$16,"") | I20: =IFERROR(ROUND(H20*$I$16,0),"") | J20: =IFERROR((I20-H20)/I20,"")
B21: 288 processing paths where up to 128 can be output busses | G21: =IF(F21-F21*$G$16=0,"",F21-F21*$G$16) | H21: =IFERROR(G21*$H$16,"") | I21: =IFERROR(ROUND(H21*$I$16,0),"") | J21: =IFERROR((I21-H21)/I21,"")
B22: 2 mono or stereo solo busses. LR, LCR. LCRS or 5.1 master buss | G22: =IF(F22-F22*$G$16=0,"",F22-F22*$G$16) | H22: =IFERROR(G22*$H$16,"") | I22: =IFERROR(ROUND(H22*$I$16,0),"") | J22: =IFERROR((I22-H22)/I22,"")
B23: 48ch USB audio I/O, 64ch plugin I/O (Fourier or Waves), 36 x 36 matrix, 36 CG/VCA, 36 FX, 32 x 32 band graphic eq’s | G23: =IF(F23-F23*$G$16=0,"",F23-F23*$G$16) | H23: =IFERROR(G23*$H$16,"") | I23: =IFERROR(ROUND(H23*$I$16,0),"") | J23: =IFERROR((I23-H23)/I23,"")
B24: 128 Nodal Processors, 64 Mustard Processors, 12 Spice FX | G24: =IF(F24-F24*$G$16=0,"",F24-F24*$G$16) | H24: =IFERROR(G24*$H$16,"") | I24: =IFERROR(ROUND(H24*$I$16,0),"") | J24: =IFERROR((I24-H24)/I24,"")
B25: Local I/O 8 x Mic/Line inputs, 8 x Line outputs, 8 x AES I/O mono stream, dust cover | G25: =IF(F25-F25*$G$16=0,"",F25-F25*$G$16) | H25: =IFERROR(G25*$H$16,"") | I25: =IFERROR(ROUND(H25*$I$16,0),"") | J25: =IFERROR((I25-H25)/I25,"")
B26: 1 x Stage SD-Rack, HMA optics, 2 BNC MADI, 2 MADI splits, dual PSU - 56 32bit mic/line in / 40 32bit line out / 16 AES out, packing carton | G26: =IF(F26-F26*$G$16=0,"",F26-F26*$G$16) | H26: =IFERROR(G26*$H$16,"") | I26: =IFERROR(ROUND(H26*$I$16,0),"") | J26: =IFERROR((I26-H26)/I26,"")
B27: 2 x 150m HMA optical cable on drum | G27: =IF(F27-F27*$G$16=0,"",F27-F27*$G$16) | H27: =IFERROR(G27*$H$16,"") | I27: =IFERROR(ROUND(H27*$I$16,0),"") | J27: =IFERROR((I27-H27)/I27,"")
B28: 1 x Touring surface flight case | G28: =IF(F28-F28*$G$16=0,"",F28-F28*$G$16) | H28: =IFERROR(G28*$H$16,"") | I28: =IFERROR(ROUND(H28*$I$16,0),"") | J28: =IFERROR((I28-H28)/I28,"")
G29: =IF(F29-F29*$G$16=0,"",F29-F29*$G$16) | H29: =IFERROR(G29*$H$16,"") | I29: =IFERROR(ROUND(H29*$I$16,0),"") | J29: =IFERROR((I29-H29)/I29,"")
A30: DiGiCo Quantum 5 Surface | E30: =ROUND(F30/0.55,0) -> 0 | G30: =IF(F30-F30*$G$16=0,"",F30-F30*$G$16) | H30: =IFERROR(G30*$H$16,"") | I30: =IFERROR(ROUND(H30*$I$16,0),"") | J30: =IFERROR((I30-H30)/I30,"")
G31: =IF(F31-F31*$G$16=0,"",F31-F31*$G$16) | H31: =IFERROR(G31*$H$16,"") | I31: =IFERROR(ROUND(H31*$I$16,0),"") | J31: =IFERROR((I31-H31)/I31,"")
A32: X-Q5-WS | B32: DiGiCo Quantum 5 Surface - MADI | E32: =ROUND(F32/0.55,0) -> 100162 | F32: 55088.88 | G32: =IF(F32-F32*$G$16=0,"",F32-F32*$G$16) -> 55088.88 | H32: =IFERROR(G32*$H$16,"") -> 8098065.4 | I32: =IFERROR(ROUND(H32*$I$16,0),"") -> 11499253 | J32: =IFERROR((I32-H32)/I32,"") -> 0.29577466
B33: Quantum 5 surface - 36+1 faders, 2 DMI slots, USB Audio I/O, 8 BNC MADI, 2 PSU, 16 GPI/O | G33: =IF(F33-F33*$G$16=0,"",F33-F33*$G$16) | H33: =IFERROR(G33*$H$16,"") | I33: =IFERROR(ROUND(H33*$I$16,0),"") | J33: =IFERROR((I33-H33)/I33,"")
B34: 288 processing paths where up to 128 can be output busses | G34: =IF(F34-F34*$G$16=0,"",F34-F34*$G$16) | H34: =IFERROR(G34*$H$16,"") | I34: =IFERROR(ROUND(H34*$I$16,0),"") | J34: =IFERROR((I34-H34)/I34,"")
B35: 2 mono or stereo solo busses. LR, LCR. LCRS or 5.1 master buss | G35: =IF(F35-F35*$G$16=0,"",F35-F35*$G$16) | H35: =IFERROR(G35*$H$16,"") | I35: =IFERROR(ROUND(H35*$I$16,0),"") | J35: =IFERROR((I35-H35)/I35,"")
B36: 48ch USB audio I/O, 36 x 36 matrix, 36 CG/VCA, 36 FX, 32 x 32 band graphic eq’s | G36: =IF(F36-F36*$G$16=0,"",F36-F36*$G$16) | H36: =IFERROR(G36*$H$16,"") | I36: =IFERROR(ROUND(H36*$I$16,0),"") | J36: =IFERROR((I36-H36)/I36,"")
B37: 128 Nodal Processors, 64 Mustard Processors, 12 Spice FX | G37: =IF(F37-F37*$G$16=0,"",F37-F37*$G$16) | H37: =IFERROR(G37*$H$16,"") | I37: =IFERROR(ROUND(H37*$I$16,0),"") | J37: =IFERROR((I37-H37)/I37,"")
B38: Local I/O 8 x Mic/Line inputs, 8 x Line outputs, 8 x AES I/O mono stream, dust cover | G38: =IF(F38-F38*$G$16=0,"",F38-F38*$G$16) | H38: =IFERROR(G38*$H$16,"") | I38: =IFERROR(ROUND(H38*$I$16,0),"") | J38: =IFERROR((I38-H38)/I38,"")
B39: Dimensions; 1465(w) x 838(d) x 458(h) mm Weight; 116Kg | G39: =IF(F39-F39*$G$16=0,"",F39-F39*$G$16) | H39: =IFERROR(G39*$H$16,"") | I39: =IFERROR(ROUND(H39*$I$16,0),"") | J39: =IFERROR((I39-H39)/I39,"")
G40: =IF(F40-F40*$G$16=0,"",F40-F40*$G$16) | H40: =IFERROR(G40*$H$16,"") | I40: =IFERROR(ROUND(H40*$I$16,0),"") | J40: =IFERROR((I40-H40)/I40,"")
A41: X-Q5-WS-OP | B41: DiGiCo Quantum 5 Surface - MADI / HMA optics | E41: =ROUND(F41/0.55,0) -> 107143 | F41: 58928.5 | G41: =IF(F41-F41*$G$16=0,"",F41-F41*$G$16) -> 58928.5 | H41: =IFERROR(G41*$H$16,"") -> 8662489.5 | I41: =IFERROR(ROUND(H41*$I$16,0),"") -> 12300735 | J41: =IFERROR((I41-H41)/I41,"") -> 0.29577464
B42: Quantum 5 surface - 36+1 faders, HMA optics, 2 DMI slots, USB Audio I/O, 8 BNC MADI, 2 PSU, 16 GPI/O | G42: =IF(F42-F42*$G$16=0,"",F42-F42*$G$16) | H42: =IFERROR(G42*$H$16,"") | I42: =IFERROR(ROUND(H42*$I$16,0),"") | J42: =IFERROR((I42-H42)/I42,"")
B43: 288 processing paths where up to 128 can be output busses | G43: =IF(F43-F43*$G$16=0,"",F43-F43*$G$16) | H43: =IFERROR(G43*$H$16,"") | I43: =IFERROR(ROUND(H43*$I$16,0),"") | J43: =IFERROR((I43-H43)/I43,"")
B44: 2 mono or stereo solo busses. LR, LCR. LCRS or 5.1 master buss | G44: =IF(F44-F44*$G$16=0,"",F44-F44*$G$16) | H44: =IFERROR(G44*$H$16,"") | I44: =IFERROR(ROUND(H44*$I$16,0),"") | J44: =IFERROR((I44-H44)/I44,"")
